Traceback (most recent call last):
  File "/home/mmann1123/miniconda3/envs/pygisbookgw/lib/python3.9/site-packages/nbclient/client.py", line 778, in _async_poll_for_reply
    msg = await ensure_async(self.kc.shell_channel.get_msg(timeout=new_timeout))
  File "/home/mmann1123/miniconda3/envs/pygisbookgw/lib/python3.9/site-packages/jupyter_core/utils/__init__.py", line 182, in ensure_async
    result = await obj
  File "/home/mmann1123/miniconda3/envs/pygisbookgw/lib/python3.9/site-packages/jupyter_client/channels.py", line 315, in get_msg
    raise Empty
_queue.Empty

During handling of the above exception, another exception occurred:

Traceback (most recent call last):
  File "/home/mmann1123/miniconda3/envs/pygisbookgw/lib/python3.9/site-packages/jupyter_cache/executors/utils.py", line 58, in single_nb_execution
    executenb(
  File "/home/mmann1123/miniconda3/envs/pygisbookgw/lib/python3.9/site-packages/nbclient/client.py", line 1305, in execute
    return NotebookClient(nb=nb, resources=resources, km=km, **kwargs).execute()
  File "/home/mmann1123/miniconda3/envs/pygisbookgw/lib/python3.9/site-packages/jupyter_core/utils/__init__.py", line 166, in wrapped
    return loop.run_until_complete(inner)
  File "/home/mmann1123/miniconda3/envs/pygisbookgw/lib/python3.9/asyncio/base_events.py", line 647, in run_until_complete
    return future.result()
  File "/home/mmann1123/miniconda3/envs/pygisbookgw/lib/python3.9/site-packages/nbclient/client.py", line 705, in async_execute
    await self.async_execute_cell(
  File "/home/mmann1123/miniconda3/envs/pygisbookgw/lib/python3.9/site-packages/nbclient/client.py", line 1001, in async_execute_cell
    exec_reply = await self.task_poll_for_reply
  File "/home/mmann1123/miniconda3/envs/pygisbookgw/lib/python3.9/site-packages/nbclient/client.py", line 802, in _async_poll_for_reply
    error_on_timeout_execute_reply = await self._async_handle_timeout(timeout, cell)
  File "/home/mmann1123/miniconda3/envs/pygisbookgw/lib/python3.9/site-packages/nbclient/client.py", line 852, in _async_handle_timeout
    raise CellTimeoutError.error_from_timeout_and_cell(
nbclient.exceptions.CellTimeoutError: A cell timed out while it was being executed, after 100 seconds.
The message was: Cell execution timed out.
Here is a preview of the cell contents:
-------------------
['# Obtain Census variables from the 2019 ACS at the tract level for the Commonwealth of Virginia (FIPS code: 51)', '# C17002_001E: count of ratio of income to poverty in the past 12 months (total)', '# C17002_002E: count of ratio of income to poverty in the past 12 months (< 0.50)', '# C17002_003E: count of ratio of income to poverty in the past 12 months (0.50 - 0.99)', '# B01003_001E: total population']
...
["va_census = c.acs5.state_county_tract(fields = ('NAME', 'C17002_001E', 'C17002_002E', 'C17002_003E', 'B01003_001E'),", '                                      state_fips = states.VA.fips,', '                                      county_fips = "*",', '                                      tract = "*",', '                                      year = 2017)']
-------------------

