Traceback (most recent call last):
  File "/home/mmann1123/miniconda3/envs/pygisbookgw/lib/python3.9/site-packages/jupyter_cache/executors/utils.py", line 58, in single_nb_execution
    executenb(
  File "/home/mmann1123/miniconda3/envs/pygisbookgw/lib/python3.9/site-packages/nbclient/client.py", line 1305, in execute
    return NotebookClient(nb=nb, resources=resources, km=km, **kwargs).execute()
  File "/home/mmann1123/miniconda3/envs/pygisbookgw/lib/python3.9/site-packages/jupyter_core/utils/__init__.py", line 166, in wrapped
    return loop.run_until_complete(inner)
  File "/home/mmann1123/miniconda3/envs/pygisbookgw/lib/python3.9/asyncio/base_events.py", line 647, in run_until_complete
    return future.result()
  File "/home/mmann1123/miniconda3/envs/pygisbookgw/lib/python3.9/site-packages/nbclient/client.py", line 705, in async_execute
    await self.async_execute_cell(
  File "/home/mmann1123/miniconda3/envs/pygisbookgw/lib/python3.9/site-packages/nbclient/client.py", line 1058, in async_execute_cell
    await self._check_raise_for_error(cell, cell_index, exec_reply)
  File "/home/mmann1123/miniconda3/envs/pygisbookgw/lib/python3.9/site-packages/nbclient/client.py", line 914, in _check_raise_for_error
    raise CellExecutionError.from_cell_and_msg(cell, exec_reply_content)
nbclient.exceptions.CellExecutionError: An error occurred while executing the following cell:
------------------
# Import GeoWombat
import geowombat as gw

# import plotting
import matplotlib.pyplot as plt
import matplotlib.patheffects as pe

# load data
from geowombat.data import l8_224077_20200518_B2, l8_224078_20200518_B2

fig, ax = plt.subplots(dpi=200)

with gw.open(
     filen[l8_224077_20200518_B2, l8_224078_20200518_B2],
     band_names=['blue'],
     mosaic=True,
     bounds_by='union'
 ) as src:
     src.where(src != 0).sel(band='blue').gw.imshow(robust=True, ax=ax)
 
plt.tight_layout(pad=1)

------------------

----- stderr -----
/home/mmann1123/miniconda3/envs/pygisbookgw/lib/python3.9/site-packages/tqdm/auto.py:21: TqdmWarning: IProgress not found. Please update jupyter and ipywidgets. See https://ipywidgets.readthedocs.io/en/stable/user_install.html
  from .autonotebook import tqdm as notebook_tqdm
------------------

[0;31m---------------------------------------------------------------------------[0m
[0;31mNameError[0m                                 Traceback (most recent call last)
Cell [0;32mIn[1], line 14[0m
[1;32m      9[0m [38;5;28;01mfrom[39;00m [38;5;21;01mgeowombat[39;00m[38;5;21;01m.[39;00m[38;5;21;01mdata[39;00m [38;5;28;01mimport[39;00m l8_224077_20200518_B2, l8_224078_20200518_B2
[1;32m     11[0m fig, ax [38;5;241m=[39m plt[38;5;241m.[39msubplots(dpi[38;5;241m=[39m[38;5;241m200[39m)
[1;32m     13[0m [38;5;28;01mwith[39;00m gw[38;5;241m.[39mopen(
[0;32m---> 14[0m      [43mfilen[49m[l8_224077_20200518_B2, l8_224078_20200518_B2],
[1;32m     15[0m      band_names[38;5;241m=[39m[[38;5;124m'[39m[38;5;124mblue[39m[38;5;124m'[39m],
[1;32m     16[0m      mosaic[38;5;241m=[39m[38;5;28;01mTrue[39;00m,
[1;32m     17[0m      bounds_by[38;5;241m=[39m[38;5;124m'[39m[38;5;124munion[39m[38;5;124m'[39m
[1;32m     18[0m  ) [38;5;28;01mas[39;00m src:
[1;32m     19[0m      src[38;5;241m.[39mwhere(src [38;5;241m!=[39m [38;5;241m0[39m)[38;5;241m.[39msel(band[38;5;241m=[39m[38;5;124m'[39m[38;5;124mblue[39m[38;5;124m'[39m)[38;5;241m.[39mgw[38;5;241m.[39mimshow(robust[38;5;241m=[39m[38;5;28;01mTrue[39;00m, ax[38;5;241m=[39max)
[1;32m     21[0m plt[38;5;241m.[39mtight_layout(pad[38;5;241m=[39m[38;5;241m1[39m)

[0;31mNameError[0m: name 'filen' is not defined

